While trying to import a dat file and create instance in Pyomo, it says "ValueError" as shown the picture below/questions/72846004/while-trying-to-import-a-dat-file-and-create-instance-in-pyomo-it-says-valueer72846004
